Workbook

Sheet Marketing Dashboard
B2: Marketing Performance Dashboard | AB2: Report Month End
K3: =IF(AB10="","",IF(AB10>0,"↑ "&TEXT(AB10,"0.0%"),IF(AB10<0,"↓ "&TEXT(ABS(AB10),"0.0%"),"→ 0.0%"))) -> ↓ 10.3% | AB3: =TOTAL!C3 -> 46234
AB4: Rolling Months
AB5: =TOTAL!N2 -> 18
AB6: Reporting Month Total Spend
B7: Channel | C7: Spend | D7: MQL | E7: MQA | F7: Meetings | G7: Opps Created | H7: Total Amount Created | I7: ACV Created | J7: Late Stage | K7: Cost/MQL | L7: Cost/Meeting | M7: Cost/Opp | N7: Meeting Rate (Meetings/MQL) | O7: Meeting Rate (Meetings/MQA) | P7: Opp Rate | Q7: Spend / $ Created | R7: Spend / $ Late Stage | S7: Won Deals | T7: Won Net New ACV | U7: ACV Conversion % | V7: Total Amount Won | W7: Total Lost ACV | X7: Win Rate (Decided) | AB7: =TOTAL!F14 -> 75325.15
B8: Digital | C8: =Digital!F15 -> 470640.59 | D8: =Digital!C10 -> 59 | E8: =Digital!C11 -> 52 | F8: =Digital!G10 -> 23 | G8: =Digital!K10 -> 20 | H8: =Digital!K11 -> 10457055 | I8: =Digital!K12 -> 8126285 | J8: =Digital!O11 -> 596510 | K8: =IFERROR(C8/D8,0) -> 7976.9592 | L8: =IFERROR(C8/F8,0) -> 20462.634 | M8: =IFERROR(C8/G8,0) -> 23532.03 | N8: =F8/D8 -> 0.38983051 | O8: =F8/E8 -> 0.44230769 | P8: =G8/F8 -> 0.86956522 | Q8: =IFERROR(I8/C8,0) -> 17.266435 | R8: =IFERROR(J8/C8,0) -> 1.2674427 | S8: =SUMIFS('Stage History'!$T:$T,'Stage History'!$O:$O,"Digital",'Stage History'!$P:$P,">="&EOMONTH($AB$3,-$AB$5)+1,'Stage History'!$P:$P,"<"&EOMONTH($AB$3,0)+1) -> 8 | T8: =SUMIFS('Stage History'!$L:$L,'Stage History'!$O:$O,"Digital",'Stage History'!$T:$T,1,'Stage History'!$P:$P,">="&EOMONTH($AB$3,-$AB$5)+1,'Stage History'!$P:$P,"<"&EOMONTH($AB$3,0)+1) -> 963185 | U8: =IFERROR(T8/I8,0) -> 0.1185271 | V8: =SUMIFS('Stage History'!$K:$K,'Stage History'!$O:$O,"Digital",'Stage History'!$T:$T,1,'Stage History'!$P:$P,">="&EOMONTH($AB$3,-$AB$5)+1,'Stage History'!$P:$P,"<"&EOMONTH($AB$3,0)+1) -> 2853765 | W8: =SUMIFS('Stage History'!$L:$L,'Stage History'!$O:$O,"Digital",'Stage History'!$V:$V,1,'Stage History'!$P:$P,">="&EOMONTH($AB$3,-$AB$5)+1,'Stage History'!$P:$P,"<"&EOMONTH($AB$3,0)+1) -> 1148160 | X8: =IFERROR(T8/(T8+W8),0) -> 0.45619498 | AB8: Prior Month Spend
B9: Events | C9: =Events!F15 -> 829384 | D9: =Events!C10 -> 471 | E9: =Events!C11 -> 331 | F9: =Events!G10 -> 34 | G9: =Events!K10 -> 30 | H9: =Events!K11 -> 9920447.6 | I9: =Events!K12 -> 7134407.6 | J9: =Events!O11 -> 1118283.8 | K9: =IFERROR(C9/D9,0) -> 1760.9002 | L9: =IFERROR(C9/F9,0) -> 24393.647 | M9: =IFERROR(C9/G9,0) -> 27646.133 | N9: =F9/D9 -> 0.072186837 | O9: =F9/E9 -> 0.10271903 | P9: =G9/F9 -> 0.88235294 | Q9: =IFERROR(I9/C9,0) -> 8.602056 | R9: =IFERROR(J9/C9,0) -> 1.3483306 | S9: =SUMIFS('Stage History'!$T:$T,'Stage History'!$O:$O,"Events",'Stage History'!$P:$P,">="&EOMONTH($AB$3,-$AB$5)+1,'Stage History'!$P:$P,"<"&EOMONTH($AB$3,0)+1) -> 0 | T9: =SUMIFS('Stage History'!$L:$L,'Stage History'!$O:$O,"Events",'Stage History'!$T:$T,1,'Stage History'!$P:$P,">="&EOMONTH($AB$3,-$AB$5)+1,'Stage History'!$P:$P,"<"&EOMONTH($AB$3,0)+1) -> 0 | U9: =IFERROR(T9/I9,0) -> 0 | V9: =SUMIFS('Stage History'!$K:$K,'Stage History'!$O:$O,"Events",'Stage History'!$T:$T,1,'Stage History'!$P:$P,">="&EOMONTH($AB$3,-$AB$5)+1,'Stage History'!$P:$P,"<"&EOMONTH($AB$3,0)+1) -> 0 | W9: =SUMIFS('Stage History'!$L:$L,'Stage History'!$O:$O,"Events",'Stage History'!$V:$V,1,'Stage History'!$P:$P,">="&EOMONTH($AB$3,-$AB$5)+1,'Stage History'!$P:$P,"<"&EOMONTH($AB$3,0)+1) -> 2945682 | X9: =IFERROR(T9/(T9+W9),0) -> 0 | AB9: =SUM( IFERROR(SUMIFS('Digital Spend Data'!$C$26:$C$212,'Digital Spend Data'!$B$26:$B$212,">="&EOMONTH($AB$3,-2)+1,'Digital Spend Data'!$B$26:$B$212,"<="&EOMONTH($AB$3,-1)),0), IFERROR(SUMIFS('Event Spend Raw'!$C:$C,'Event Spend Raw'!$G:$G,">="&EOMONTH($AB$3,-2)+1,'Event Spend Raw'!$G:$G,"<="&EOMONTH($AB$3,-1)),0), IFERROR(SUMIFS('Cold Outreach Spend Raw'!$B:$B,'Cold Outreach Spend Raw'!$A:$A,">="&EOMONTH($AB$3,-2)+1,'Cold Outreach Spend Raw'!$A:$A,"<="&EOMONTH($AB$3,-1)),0), IFERROR(SUMIFS('Alliances Spend'!$B:$B,'Alliances Spend'!$C:$C,">="&EOMONTH($AB$3,-2)+1,'Alliances Spend'!$C:$C,"<="&EOMONTH($AB$3,-1)),0) ) -> 83937.21
B10: Cold | C10: ='Cold Outreach'!F15 -> 479675 | D10: ='Cold Outreach'!C10 -> 178 | E10: ='Cold Outreach'!C11 -> 138 | F10: ='Cold Outreach'!G10 -> 141 | G10: ='Cold Outreach'!K10 -> 27 | H10: ='Cold Outreach'!K11 -> 10098778 | I10: ='Cold Outreach'!K12 -> 6961560 | J10: ='Cold Outreach'!O11 -> 1267200 | K10: =IFERROR(C10/D10,0) -> 2694.8034 | L10: =IFERROR(C10/F10,0) -> 3401.9504 | M10: =IFERROR(C10/G10,0) -> 17765.741 | N10: =F10/D10 -> 0.79213483 | O10: =F10/E10 -> 1.0217391 | P10: =G10/F10 -> 0.19148936 | Q10: =IFERROR(I10/C10,0) -> 14.513077 | R10: =IFERROR(J10/C10,0) -> 2.6417887 | S10: =SUMIFS('Stage History'!$T:$T,'Stage History'!$O:$O,"Cold",'Stage History'!$P:$P,">="&EOMONTH($AB$3,-$AB$5)+1,'Stage History'!$P:$P,"<"&EOMONTH($AB$3,0)+1) -> 4 | T10: =SUMIFS('Stage History'!$L:$L,'Stage History'!$O:$O,"Cold",'Stage History'!$T:$T,1,'Stage History'!$P:$P,">="&EOMONTH($AB$3,-$AB$5)+1,'Stage History'!$P:$P,"<"&EOMONTH($AB$3,0)+1) -> 219385.5 | U10: =IFERROR(T10/I10,0) -> 0.031513842 | V10: =SUMIFS('Stage History'!$K:$K,'Stage History'!$O:$O,"Cold",'Stage History'!$T:$T,1,'Stage History'!$P:$P,">="&EOMONTH($AB$3,-$AB$5)+1,'Stage History'!$P:$P,"<"&EOMONTH($AB$3,0)+1) -> 331395.25 | W10: =SUMIFS('Stage History'!$L:$L,'Stage History'!$O:$O,"Cold",'Stage History'!$V:$V,1,'Stage History'!$P:$P,">="&EOMONTH($AB$3,-$AB$5)+1,'Stage History'!$P:$P,"<"&EOMONTH($AB$3,0)+1) -> 7774120 | X10: =IFERROR(T10/(T10+W10),0) -> 0.027445468 | AB10: =IF(AB9=0,"",(AB7-AB9)/AB9) -> -0.10260122 | AC10: MoM%
B11: Alliances | C11: =Alliances!F15 -> 188072.1 | D11: =Alliances!C10 -> 114 | E11: =Alliances!C11 -> 107 | F11: =Alliances!G10 -> 71 | G11: =Alliances!K10 -> 56 | H11: =Alliances!K11 -> 30153720 | I11: =Alliances!K12 -> 18115520 | J11: =Alliances!O11 -> 907364 | K11: =IFERROR(C11/D11,0) -> 1649.7553 | L11: =IFERROR(C11/F11,0) -> 2648.9028 | M11: =IFERROR(C11/G11,0) -> 3358.4304 | N11: =F11/D11 -> 0.62280702 | O11: =F11/E11 -> 0.6635514 | P11: =G11/F11 -> 0.78873239 | Q11: =IFERROR(I11/C11,0) -> 96.322209 | R11: =IFERROR(J11/C11,0) -> 4.824554 | S11: =SUMIFS('Stage History'!$T:$T,'Stage History'!$O:$O,"Alliances",'Stage History'!$P:$P,">="&EOMONTH($AB$3,-$AB$5)+1,'Stage History'!$P:$P,"<"&EOMONTH($AB$3,0)+1) -> 19 | T11: =SUMIFS('Stage History'!$L:$L,'Stage History'!$O:$O,"Alliances",'Stage History'!$T:$T,1,'Stage History'!$P:$P,">="&EOMONTH($AB$3,-$AB$5)+1,'Stage History'!$P:$P,"<"&EOMONTH($AB$3,0)+1) -> 1855153.6 | U11: =IFERROR(T11/I11,0) -> 0.10240686 | V11: =SUMIFS('Stage History'!$K:$K,'Stage History'!$O:$O,"Alliances",'Stage History'!$T:$T,1,'Stage History'!$P:$P,">="&EOMONTH($AB$3,-$AB$5)+1,'Stage History'!$P:$P,"<"&EOMONTH($AB$3,0)+1) -> 3307393.6 | W11: =SUMIFS('Stage History'!$L:$L,'Stage History'!$O:$O,"Alliances",'Stage History'!$V:$V,1,'Stage History'!$P:$P,">="&EOMONTH($AB$3,-$AB$5)+1,'Stage History'!$P:$P,"<"&EOMONTH($AB$3,0)+1) -> 6686773 | X11: =IFERROR(T11/(T11+W11),0) -> 0.2171821 | AB11: =IF(AB10="","", IF(AB10>=0, "↑ "&TEXT(AB10,"0.0%"), "↓ "&TEXT(ABS(AB10),"0.0%") )) -> ↓ 10.3% | AC11: arrow
B12: TOTAL | C12: =SUM(C8:C11) -> 1967771.7 | D12: =SUM(D8:D11) -> 822 | E12: =SUM(E8:E11) -> 628 | F12: =SUM(F8:F11) -> 269 | G12: =SUM(G8:G11) -> 133 | H12: =SUM(H8:H11) -> 60630001 | I12: =SUM(I8:I11) -> 40337773 | J12: =SUM(J8:J11) -> 3889357.8 | K12: =IFERROR(C12/D12,0) -> 2393.8828 | L12: =IFERROR(C12/F12,0) -> 7315.1364 | M12: =IFERROR(C12/G12,0) -> 14795.276 | N12: =F12/D12 -> 0.32725061 | O12: =F12/E12 -> 0.42834395 | P12: =G12/F12 -> 0.49442379 | Q12: =IFERROR(H12/C12,0) -> 30.811502 | R12: =IFERROR(J12/C12,0) -> 1.976529 | S12: =SUM(S8:S11) -> 31 | T12: =SUM(T8:T11) -> 3037724.1 | U12: =IFERROR(T12/I12,0) -> 0.075307184 | V12: =SUM(V8:V11) -> 6492553.8 | W12: =SUM(W8:W11) -> 18554735 | X12: =IFERROR(T12/(T12+W12),0) -> 0.14068449 | AB12: =IFERROR("vs "&TEXT(EOMONTH($AB$3,-1),"mmm-yy")&" ("&TEXT(VALUE(AB9),"$#,##0")&")","") -> vs Jun-26 ($83,937) | AC12: comparison text
AB13: =IF(AB10>0,"↑ "&TEXT(AB10,"0.0%"),"") | AC13: red helper
AB14: green helper
B15: 12-Month Trend | J15: MoM Spend by Channel | O15: Opp Quality by Channel | AC15: =IF(C2=0,"",(B2-C2)/C2) | AD15: channel spend helper
B16: Month Created | C16: Opps Created | D16: Amount Created | E16: MQL | F16: Meetings | G16: Avg Deal Size | H16: Late Stage | J16: Channel | K16: =TEXT($AB$3,"mmmm")&" Spend" -> July Spend | L16: =TEXT(EOMONTH($AB$3,-1),"mmmm")&" Spend" -> June Spend | M16: % Change | O16: Channel | P16: Open Opps | Q16: Avg ACV | R16: % with ACV > $0 | S16: Avg Opp Age (days) | T16: Avg Stage Duration | U16: Late Stage %
B17: =EOMONTH($AB$3,-11) -> 45900 | C17: =COUNTIFS('Opps Created'!$G:$G,">="&EOMONTH($B17,-1)+1,'Opps Created'!$G:$G,"<="&EOMONTH($B17,0),'Opps Created'!$O:$O,"<>",'Opps Created'!$O:$O,"<>0",'Opps Created'!$O:$O,"<>Exclude") -> 5 | D17: =SUM( SUMIFS('Opps Created'!$E:$E,'Opps Created'!$O:$O,"Digital",'Opps Created'!$G:$G,">="&EOMONTH($B17,-1)+1,'Opps Created'!$G:$G,"<="&EOMONTH($B17,0)), SUMIFS('Opps Created'!$E:$E,'Opps Created'!$O:$O,"Events",'Opps Created'!$G:$G,">="&EOMONTH($B17,-1)+1,'Opps Created'!$G:$G,"<="&EOMONTH($B17,0)), SUMIFS('Opps Created'!$E:$E,'Opps Created'!$O:$O,"Alliances",'Opps Created'!$G:$G,">="&EOMONTH($B17,-1)+1,'Opps Created'!$G:$G,"<="&EOMONTH($B17,0)), SUMIFS('Opps Created'!$E:$E,'Opps Created'!$O:$O,"Cold",'Opps Created'!$G:$G,">="&EOMONTH($B17,-1)+1,'Opps Created'!$G:$G,"<="&EOMONTH($B17,0)) ) -> 3009200 | E17: =SUMIFS('Digital Leads Raw'!$B:$B,'Digital Leads Raw'!$E:$E,">="&EOMONTH($B17,-1)+1,'Digital Leads Raw'!$E:$E,"<="&EOMONTH($B17,0)) +SUMIFS('Event Spend Raw'!$D:$D,'Event Spend Raw'!$G:$G,">="&EOMONTH($B17,-1)+1,'Event Spend Raw'!$G:$G,"<="&EOMONTH($B17,0)) +COUNTIFS('Cold outreach data'!$K:$K,"Cold",'Cold outreach data'!$C:$C,">="&EOMONTH($B17,-1)+1,'Cold outreach data'!$C:$C,"<="&EOMONTH($B17,0)) +COUNTIFS('Alliances Data Raw'!$Q:$Q,">="&EOMONTH($B17,-1)+1,'Alliances Data Raw'!$Q:$Q,"<="&EOMONTH($B17,0),'Alliances Data Raw'!$D:$D,"<>Disqualified",'Alliances Data Raw'!$D:$D,"<>Register Lead") -> 58 | F17: =COUNTIFS('Cold outreach data'!$G:$G,"Yes",'Cold outreach data'!$K:$K,"Digital",'Cold outreach data'!$C:$C,">="&EOMONTH($B17,-1)+1,'Cold outreach data'!$C:$C,"<="&EOMONTH($B17,0))+COUNTIFS('Cold outreach data'!$G:$G,"Yes",'Cold outreach data'!$K:$K,"Event",'Cold outreach data'!$C:$C,">="&EOMONTH($B17,-1)+1,'Cold outreach data'!$C:$C,"<="&EOMONTH($B17,0))+COUNTIFS('Cold outreach data'!$G:$G,"Yes",'Cold outreach data'!$K:$K,"Cold",'Cold outreach data'!$C:$C,">="&EOMONTH($B17,-1)+1,'Cold outreach data'!$C:$C,"<="&EOMONTH($B17,0))+COUNTIFS('Alliances Data Raw'!$W:$W,">="&EOMONTH($B17,-1)+1,'Alliances Data Raw'!$W:$W,"<="&EOMONTH($B17,0)) -> 20 | G17: =D17/C17 -> 601840 | H17: =SUMIFS( Table1[Total Net New ACV], Table1[LateStage_Unique_Monthly_Flag], 1, Table1[Change Date], ">="&EOMONTH('Marketing Dashboard'!B17,-1)+1, Table1[Change Date], "<="&EOMONTH('Marketing Dashboard'!B17,0) ) -> 1888583.9 | J17: Digital | K17: =SUMIFS( 'Digital Spend Data'!$C$26:$C$212, 'Digital Spend Data'!$B$26:$B$212,">="&EOMONTH($AB$3,-1)+1, 'Digital Spend Data'!$B$26:$B$212,"<="&EOMONTH($AB$3,0) ) -> 34395.59 | L17: =SUMIFS( 'Digital Spend Data'!$C$26:$C$212, 'Digital Spend Data'!$B$26:$B$212,">="&EOMONTH($AB$3,-2)+1, 'Digital Spend Data'!$B$26:$B$212,"<="&EOMONTH($AB$3,-1) ) -> 31769.46 | M17: =IF(L17=0,"", IF((K17-L17)/L17>0, "↑ "&TEXT((K17-L17)/L17,"0.0%"), IF((K17-L17)/L17<0, "↓ "&TEXT(ABS((K17-L17)/L17),"0.0%"), "→ 0.0%" ))) -> ↑ 8.3% | O17: Digital | P17: =COUNTIFS('Opps Created'!$O:$O,"Digital",'Opps Created'!$R:$R,0,'Opps Created'!$G:$G,">="&EOMONTH($AB$3,-$AB$5)+1,'Opps Created'!$G:$G,"<="&$AB$3) -> 17 | Q17: =IFERROR(AVERAGEIFS('Opps Created'!$M:$M,'Opps Created'!$O:$O,"Digital",'Opps Created'!$R:$R,0,'Opps Created'!$M:$M,">0",'Opps Created'!$G:$G,">="&EOMONTH($AB$3,-$AB$5)+1,'Opps Created'!$G:$G,"<="&$AB$3),0) -> 493518.75 | R17: =IFERROR(COUNTIFS('Opps Created'!$O:$O,"Digital",'Opps Created'!$R:$R,0,'Opps Created'!$M:$M,">0",'Opps Created'!$G:$G,">="&EOMONTH($AB$3,-$AB$5)+1,'Opps Created'!$G:$G,"<="&$AB$3)/P17,0) -> 0.94117647 | S17: =IFERROR(AVERAGEIFS('Opps Created'!$P:$P,'Opps Created'!$O:$O,"Digital",'Opps Created'!$R:$R,0,'Opps Created'!$G:$G,">="&EOMONTH($AB$3,-$AB$5)+1,'Opps Created'!$G:$G,"<="&$AB$3),0) -> 369.52941 | T17: =IFERROR(AVERAGEIFS('Opps Created'!$N:$N,'Opps Created'!$O:$O,"Digital",'Opps Created'!$R:$R,0,'Opps Created'!$G:$G,">="&EOMONTH($AB$3,-$AB$5)+1,'Opps Created'!$G:$G,"<="&$AB$3),0) -> 187.35294 | U17: =IFERROR(COUNTIFS('Opps Created'!$O:$O,"Digital",'Opps Created'!$R:$R,0,'Opps Created'!$Q:$Q,1,'Opps Created'!$G:$G,">="&EOMONTH($AB$3,-$AB$5)+1,'Opps Created'!$G:$G,"<="&$AB$3)/P17,0) -> 0
B18: =EOMONTH($AB$3,-10) -> 45930 | C18: =COUNTIFS('Opps Created'!$G:$G,">="&EOMONTH($B18,-1)+1,'Opps Created'!$G:$G,"<="&EOMONTH($B18,0),'Opps Created'!$O:$O,"<>",'Opps Created'!$O:$O,"<>0",'Opps Created'!$O:$O,"<>Exclude") -> 12 | D18: =SUM( SUMIFS('Opps Created'!$E:$E,'Opps Created'!$O:$O,"Digital",'Opps Created'!$G:$G,">="&EOMONTH($B18,-1)+1,'Opps Created'!$G:$G,"<="&EOMONTH($B18,0)), SUMIFS('Opps Created'!$E:$E,'Opps Created'!$O:$O,"Events",'Opps Created'!$G:$G,">="&EOMONTH($B18,-1)+1,'Opps Created'!$G:$G,"<="&EOMONTH($B18,0)), SUMIFS('Opps Created'!$E:$E,'Opps Created'!$O:$O,"Alliances",'Opps Created'!$G:$G,">="&EOMONTH($B18,-1)+1,'Opps Created'!$G:$G,"<="&EOMONTH($B18,0)), SUMIFS('Opps Created'!$E:$E,'Opps Created'!$O:$O,"Cold",'Opps Created'!$G:$G,">="&EOMONTH($B18,-1)+1,'Opps Created'!$G:$G,"<="&EOMONTH($B18,0)) ) -> 15218160 | E18: =SUMIFS('Digital Leads Raw'!$B:$B,'Digital Leads Raw'!$E:$E,">="&EOMONTH($B18,-1)+1,'Digital Leads Raw'!$E:$E,"<="&EOMONTH($B18,0)) +SUMIFS('Event Spend Raw'!$D:$D,'Event Spend Raw'!$G:$G,">="&EOMONTH($B18,-1)+1,'Event Spend Raw'!$G:$G,"<="&EOMONTH($B18,0)) +COUNTIFS('Cold outreach data'!$K:$K,"Cold",'Cold outreach data'!$C:$C,">="&EOMONTH($B18,-1)+1,'Cold outreach data'!$C:$C,"<="&EOMONTH($B18,0)) +COUNTIFS('Alliances Data Raw'!$Q:$Q,">="&EOMONTH($B18,-1)+1,'Alliances Data Raw'!$Q:$Q,"<="&EOMONTH($B18,0),'Alliances Data Raw'!$D:$D,"<>Disqualified",'Alliances Data Raw'!$D:$D,"<>Register Lead") -> 64 | F18: =COUNTIFS('Cold outreach data'!$G:$G,"Yes",'Cold outreach data'!$K:$K,"Digital",'Cold outreach data'!$C:$C,">="&EOMONTH($B18,-1)+1,'Cold outreach data'!$C:$C,"<="&EOMONTH($B18,0))+COUNTIFS('Cold outreach data'!$G:$G,"Yes",'Cold outreach data'!$K:$K,"Event",'Cold outreach data'!$C:$C,">="&EOMONTH($B18,-1)+1,'Cold outreach data'!$C:$C,"<="&EOMONTH($B18,0))+COUNTIFS('Cold outreach data'!$G:$G,"Yes",'Cold outreach data'!$K:$K,"Cold",'Cold outreach data'!$C:$C,">="&EOMONTH($B18,-1)+1,'Cold outreach data'!$C:$C,"<="&EOMONTH($B18,0))+COUNTIFS('Alliances Data Raw'!$W:$W,">="&EOMONTH($B18,-1)+1,'Alliances Data Raw'!$W:$W,"<="&EOMONTH($B18,0)) -> 13 | G18: =D18/C18 -> 1268180 | H18: =SUMIFS( Table1[Total Net New ACV], Table1[LateStage_Unique_Monthly_Flag], 1, Table1[Change Date], ">="&EOMONTH('Marketing Dashboard'!B18,-1)+1, Table1[Change Date], "<="&EOMONTH('Marketing Dashboard'!B18,0) ) -> 1465250.7 | J18: Events | K18: =SUMIFS( 'Event Spend Raw'!$C:$C, 'Event Spend Raw'!$G:$G,">="&EOMONTH($AB$3,-1)+1, 'Event Spend Raw'!$G:$G,"<="&EOMONTH($AB$3,0) ) -> 5000 | L18: =SUMIFS( 'Event Spend Raw'!$C:$C, 'Event Spend Raw'!$G:$G,">="&EOMONTH($AB$3,-2)+1, 'Event Spend Raw'!$G:$G,"<="&EOMONTH($AB$3,-1) ) -> 19600 | M18: =IF(L18=0,"", IF((K18-L18)/L18>0, "↑ "&TEXT((K18-L18)/L18,"0.0%"), IF((K18-L18)/L18<0, "↓ "&TEXT(ABS((K18-L18)/L18),"0.0%"), "→ 0.0%" ))) -> ↓ 74.5% | O18: Events | P18: =COUNTIFS('Opps Created'!$O:$O,"Events",'Opps Created'!$R:$R,0,'Opps Created'!$G:$G,">="&EOMONTH($AB$3,-$AB$5)+1,'Opps Created'!$G:$G,"<="&$AB$3) -> 30 | Q18: =IFERROR(AVERAGEIFS('Opps Created'!$M:$M,'Opps Created'!$O:$O,"Events",'Opps Created'!$R:$R,0,'Opps Created'!$M:$M,">0",'Opps Created'!$G:$G,">="&EOMONTH($AB$3,-$AB$5)+1,'Opps Created'!$G:$G,"<="&$AB$3),0) -> 285376.3 | R18: =IFERROR(COUNTIFS('Opps Created'!$O:$O,"Events",'Opps Created'!$R:$R,0,'Opps Created'!$M:$M,">0",'Opps Created'!$G:$G,">="&EOMONTH($AB$3,-$AB$5)+1,'Opps Created'!$G:$G,"<="&$AB$3)/P18,0) -> 0.83333333 | S18: =IFERROR(AVERAGEIFS('Opps Created'!$P:$P,'Opps Created'!$O:$O,"Events",'Opps Created'!$R:$R,0,'Opps Created'!$G:$G,">="&EOMONTH($AB$3,-$AB$5)+1,'Opps Created'!$G:$G,"<="&$AB$3),0) -> 279.73333 | T18: =IFERROR(AVERAGEIFS('Opps Created'!$N:$N,'Opps Created'!$O:$O,"Events",'Opps Created'!$R:$R,0,'Opps Created'!$G:$G,">="&EOMONTH($AB$3,-$AB$5)+1,'Opps Created'!$G:$G,"<="&$AB$3),0) -> 164.03333 | U18: =IFERROR(COUNTIFS('Opps Created'!$O:$O,"Events",'Opps Created'!$R:$R,0,'Opps Created'!$Q:$Q,1,'Opps Created'!$G:$G,">="&EOMONTH($AB$3,-$AB$5)+1,'Opps Created'!$G:$G,"<="&$AB$3)/P18,0) -> 0.1
B19: =EOMONTH($AB$3,-9) -> 45961 | C19: =COUNTIFS('Opps Created'!$G:$G,">="&EOMONTH($B19,-1)+1,'Opps Created'!$G:$G,"<="&EOMONTH($B19,0),'Opps Created'!$O:$O,"<>",'Opps Created'!$O:$O,"<>0",'Opps Created'!$O:$O,"<>Exclude") -> 7 | D19: =SUM( SUMIFS('Opps Created'!$E:$E,'Opps Created'!$O:$O,"Digital",'Opps Created'!$G:$G,">="&EOMONTH($B19,-1)+1,'Opps Created'!$G:$G,"<="&EOMONTH($B19,0)), SUMIFS('Opps Created'!$E:$E,'Opps Created'!$O:$O,"Events",'Opps Created'!$G:$G,">="&EOMONTH($B19,-1)+1,'Opps Created'!$G:$G,"<="&EOMONTH($B19,0)), SUMIFS('Opps Created'!$E:$E,'Opps Created'!$O:$O,"Alliances",'Opps Created'!$G:$G,">="&EOMONTH($B19,-1)+1,'Opps Created'!$G:$G,"<="&EOMONTH($B19,0)), SUMIFS('Opps Created'!$E:$E,'Opps Created'!$O:$O,"Cold",'Opps Created'!$G:$G,">="&EOMONTH($B19,-1)+1,'Opps Created'!$G:$G,"<="&EOMONTH($B19,0)) ) -> 1241516.2 | E19: =SUMIFS('Digital Leads Raw'!$B:$B,'Digital Leads Raw'!$E:$E,">="&EOMONTH($B19,-1)+1,'Digital Leads Raw'!$E:$E,"<="&EOMONTH($B19,0)) +SUMIFS('Event Spend Raw'!$D:$D,'Event Spend Raw'!$G:$G,">="&EOMONTH($B19,-1)+1,'Event Spend Raw'!$G:$G,"<="&EOMONTH($B19,0)) +COUNTIFS('Cold outreach data'!$K:$K,"Cold",'Cold outreach data'!$C:$C,">="&EOMONTH($B19,-1)+1,'Cold outreach data'!$C:$C,"<="&EOMONTH($B19,0)) +COUNTIFS('Alliances Data Raw'!$Q:$Q,">="&EOMONTH($B19,-1)+1,'Alliances Data Raw'!$Q:$Q,"<="&EOMONTH($B19,0),'Alliances Data Raw'!$D:$D,"<>Disqualified",'Alliances Data Raw'!$D:$D,"<>Register Lead") -> 22 | F19: =COUNTIFS('Cold outreach data'!$G:$G,"Yes",'Cold outreach data'!$K:$K,"Digital",'Cold outreach data'!$C:$C,">="&EOMONTH($B19,-1)+1,'Cold outreach data'!$C:$C,"<="&EOMONTH($B19,0))+COUNTIFS('Cold outreach data'!$G:$G,"Yes",'Cold outreach data'!$K:$K,"Event",'Cold outreach data'!$C:$C,">="&EOMONTH($B19,-1)+1,'Cold outreach data'!$C:$C,"<="&EOMONTH($B19,0))+COUNTIFS('Cold outreach data'!$G:$G,"Yes",'Cold outreach data'!$K:$K,"Cold",'Cold outreach data'!$C:$C,">="&EOMONTH($B19,-1)+1,'Cold outreach data'!$C:$C,"<="&EOMONTH($B19,0))+COUNTIFS('Alliances Data Raw'!$W:$W,">="&EOMONTH($B19,-1)+1,'Alliances Data Raw'!$W:$W,"<="&EOMONTH($B19,0)) -> 18 | G19: =D19/C19 -> 177359.45 | H19: =SUMIFS( Table1[Total Net New ACV], Table1[LateStage_Unique_Monthly_Flag], 1, Table1[Change Date], ">="&EOMONTH('Marketing Dashboard'!B19,-1)+1, Table1[Change Date], "<="&EOMONTH('Marketing Dashboard'!B19,0) ) -> 2278803.3 | J19: Cold Outreach | K19: =SUMIFS( 'Cold Outreach Spend Raw'!$B:$B, 'Cold Outreach Spend Raw'!$A:$A,">="&EOMONTH($AB$3,-1)+1, 'Cold Outreach Spend Raw'!$A:$A,"<="&EOMONTH($AB$3,0) ) -> 32475 | L19: =SUMIFS( 'Cold Outreach Spend Raw'!$B:$B, 'Cold Outreach Spend Raw'!$A:$A,">="&EOMONTH($AB$3,-2)+1, 'Cold Outreach Spend Raw'!$A:$A,"<="&EOMONTH($AB$3,-1) ) -> 32475 | M19: =IF(L19=0,"", IF((K19-L19)/L19>0, "↑ "&TEXT((K19-L19)/L19,"0.0%"), IF((K19-L19)/L19<0, "↓ "&TEXT(ABS((K19-L19)/L19),"0.0%"), "→ 0.0%" ))) -> → 0.0% | O19: Cold Outreach | P19: =COUNTIFS('Opps Created'!$O:$O,"Cold",'Opps Created'!$R:$R,0,'Opps Created'!$G:$G,">="&EOMONTH($AB$3,-$AB$5)+1,'Opps Created'!$G:$G,"<="&$AB$3) -> 25 | Q19: =IFERROR(AVERAGEIFS('Opps Created'!$M:$M,'Opps Created'!$O:$O,"Cold",'Opps Created'!$R:$R,0,'Opps Created'!$M:$M,">0",'Opps Created'!$G:$G,">="&EOMONTH($AB$3,-$AB$5)+1,'Opps Created'!$G:$G,"<="&$AB$3),0) -> 324979.05 | R19: =IFERROR(COUNTIFS('Opps Created'!$O:$O,"Cold",'Opps Created'!$R:$R,0,'Opps Created'!$M:$M,">0",'Opps Created'!$G:$G,">="&EOMONTH($AB$3,-$AB$5)+1,'Opps Created'!$G:$G,"<="&$AB$3)/P19,0) -> 0.84 | S19: =IFERROR(AVERAGEIFS('Opps Created'!$P:$P,'Opps Created'!$O:$O,"Cold",'Opps Created'!$R:$R,0,'Opps Created'!$G:$G,">="&EOMONTH($AB$3,-$AB$5)+1,'Opps Created'!$G:$G,"<="&$AB$3),0) -> 320.52 | T19: =IFERROR(AVERAGEIFS('Opps Created'!$N:$N,'Opps Created'!$O:$O,"Cold",'Opps Created'!$R:$R,0,'Opps Created'!$G:$G,">="&EOMONTH($AB$3,-$AB$5)+1,'Opps Created'!$G:$G,"<="&$AB$3),0) -> 158.52 | U19: =IFERROR(COUNTIFS('Opps Created'!$O:$O,"Cold",'Opps Created'!$R:$R,0,'Opps Created'!$Q:$Q,1,'Opps Created'!$G:$G,">="&EOMONTH($AB$3,-$AB$5)+1,'Opps Created'!$G:$G,"<="&$AB$3)/P19,0) -> 0.08
B20: =EOMONTH($AB$3,-8) -> 45991 | C20: =COUNTIFS('Opps Created'!$G:$G,">="&EOMONTH($B20,-1)+1,'Opps Created'!$G:$G,"<="&EOMONTH($B20,0),'Opps Created'!$O:$O,"<>",'Opps Created'!$O:$O,"<>0",'Opps Created'!$O:$O,"<>Exclude") -> 6 | D20: =SUM( SUMIFS('Opps Created'!$E:$E,'Opps Created'!$O:$O,"Digital",'Opps Created'!$G:$G,">="&EOMONTH($B20,-1)+1,'Opps Created'!$G:$G,"<="&EOMONTH($B20,0)), SUMIFS('Opps Created'!$E:$E,'Opps Created'!$O:$O,"Events",'Opps Created'!$G:$G,">="&EOMONTH($B20,-1)+1,'Opps Created'!$G:$G,"<="&EOMONTH($B20,0)), SUMIFS('Opps Created'!$E:$E,'Opps Created'!$O:$O,"Alliances",'Opps Created'!$G:$G,">="&EOMONTH($B20,-1)+1,'Opps Created'!$G:$G,"<="&EOMONTH($B20,0)), SUMIFS('Opps Created'!$E:$E,'Opps Created'!$O:$O,"Cold",'Opps Created'!$G:$G,">="&EOMONTH($B20,-1)+1,'Opps Created'!$G:$G,"<="&EOMONTH($B20,0)) ) -> 1441015.6 | E20: =SUMIFS('Digital Leads Raw'!$B:$B,'Digital Leads Raw'!$E:$E,">="&EOMONTH($B20,-1)+1,'Digital Leads Raw'!$E:$E,"<="&EOMONTH($B20,0)) +SUMIFS('Event Spend Raw'!$D:$D,'Event Spend Raw'!$G:$G,">="&EOMONTH($B20,-1)+1,'Event Spend Raw'!$G:$G,"<="&EOMONTH($B20,0)) +COUNTIFS('Cold outreach data'!$K:$K,"Cold",'Cold outreach data'!$C:$C,">="&EOMONTH($B20,-1)+1,'Cold outreach data'!$C:$C,"<="&EOMONTH($B20,0)) +COUNTIFS('Alliances Data Raw'!$Q:$Q,">="&EOMONTH($B20,-1)+1,'Alliances Data Raw'!$Q:$Q,"<="&EOMONTH($B20,0),'Alliances Data Raw'!$D:$D,"<>Disqualified",'Alliances Data Raw'!$D:$D,"<>Register Lead") -> 78 | F20: =COUNTIFS('Cold outreach data'!$G:$G,"Yes",'Cold outreach data'!$K:$K,"Digital",'Cold outreach data'!$C:$C,">="&EOMONTH($B20,-1)+1,'Cold outreach data'!$C:$C,"<="&EOMONTH($B20,0))+COUNTIFS('Cold outreach data'!$G:$G,"Yes",'Cold outreach data'!$K:$K,"Event",'Cold outreach data'!$C:$C,">="&EOMONTH($B20,-1)+1,'Cold outreach data'!$C:$C,"<="&EOMONTH($B20,0))+COUNTIFS('Cold outreach data'!$G:$G,"Yes",'Cold outreach data'!$K:$K,"Cold",'Cold outreach data'!$C:$C,">="&EOMONTH($B20,-1)+1,'Cold outreach data'!$C:$C,"<="&EOMONTH($B20,0))+COUNTIFS('Alliances Data Raw'!$W:$W,">="&EOMONTH($B20,-1)+1,'Alliances Data Raw'!$W:$W,"<="&EOMONTH($B20,0)) -> 14 | G20: =D20/C20 -> 240169.27 | H20: =SUMIFS( Table1[Total Net New ACV], Table1[LateStage_Unique_Monthly_Flag], 1, Table1[Change Date], ">="&EOMONTH('Marketing Dashboard'!B20,-1)+1, Table1[Change Date], "<="&EOMONTH('Marketing Dashboard'!B20,0) ) -> 854808 | J20: Alliances | K20: =SUMIFS( 'Alliances Spend'!$B:$B, 'Alliances Spend'!$C:$C,">="&EOMONTH($AB$3,-1)+1, 'Alliances Spend'!$C:$C,"<="&EOMONTH($AB$3,0) ) -> 3454.56 | L20: =SUMIFS( 'Alliances Spend'!$B:$B, 'Alliances Spend'!$C:$C,">="&EOMONTH($AB$3,-2)+1, 'Alliances Spend'!$C:$C,"<="&EOMONTH($AB$3,-1) ) -> 92.75 | M20: =IF(L20=0,"", IF((K20-L20)/L20>0, "↑ "&TEXT((K20-L20)/L20,"0.0%"), IF((K20-L20)/L20<0, "↓ "&TEXT(ABS((K20-L20)/L20),"0.0%"), "→ 0.0%" ))) -> ↑ 3624.6% | O20: Alliances | P20: =COUNTIFS('Opps Created'!$O:$O,"Alliances",'Opps Created'!$R:$R,0,'Opps Created'!$G:$G,">="&EOMONTH($AB$3,-$AB$5)+1,'Opps Created'!$G:$G,"<="&$AB$3) -> 46 | Q20: =IFERROR(AVERAGEIFS('Opps Created'!$M:$M,'Opps Created'!$O:$O,"Alliances",'Opps Created'!$R:$R,0,'Opps Created'!$M:$M,">0",'Opps Created'!$G:$G,">="&EOMONTH($AB$3,-$AB$5)+1,'Opps Created'!$G:$G,"<="&$AB$3),0) -> 418501.26 | R20: =IFERROR(COUNTIFS('Opps Created'!$O:$O,"Alliances",'Opps Created'!$R:$R,0,'Opps Created'!$M:$M,">0",'Opps Created'!$G:$G,">="&EOMONTH($AB$3,-$AB$5)+1,'Opps Created'!$G:$G,"<="&$AB$3)/P20,0) -> 0.89130435 | S20: =IFERROR(AVERAGEIFS('Opps Created'!$P:$P,'Opps Created'!$O:$O,"Alliances",'Opps Created'!$R:$R,0,'Opps Created'!$G:$G,">="&EOMONTH($AB$3,-$AB$5)+1,'Opps Created'!$G:$G,"<="&$AB$3),0) -> 273.15217 | T20: =IFERROR(AVERAGEIFS('Opps Created'!$N:$N,'Opps Created'!$O:$O,"Alliances",'Opps Created'!$R:$R,0,'Opps Created'!$G:$G,">="&EOMONTH($AB$3,-$AB$5)+1,'Opps Created'!$G:$G,"<="&$AB$3),0) -> 189.26087 | U20: =IFERROR(COUNTIFS('Opps Created'!$O:$O,"Alliances",'Opps Created'!$R:$R,0,'Opps Created'!$Q:$Q,1,'Opps Created'!$G:$G,">="&EOMONTH($AB$3,-$AB$5)+1,'Opps Created'!$G:$G,"<="&$AB$3)/P20,0) -> 0.086956522
B21: =EOMONTH($AB$3,-7) -> 46022 | C21: =COUNTIFS('Opps Created'!$G:$G,">="&EOMONTH($B21,-1)+1,'Opps Created'!$G:$G,"<="&EOMONTH($B21,0),'Opps Created'!$O:$O,"<>",'Opps Created'!$O:$O,"<>0",'Opps Created'!$O:$O,"<>Exclude") -> 7 | D21: =SUM( SUMIFS('Opps Created'!$E:$E,'Opps Created'!$O:$O,"Digital",'Opps Created'!$G:$G,">="&EOMONTH($B21,-1)+1,'Opps Created'!$G:$G,"<="&EOMONTH($B21,0)), SUMIFS('Opps Created'!$E:$E,'Opps Created'!$O:$O,"Events",'Opps Created'!$G:$G,">="&EOMONTH($B21,-1)+1,'Opps Created'!$G:$G,"<="&EOMONTH($B21,0)), SUMIFS('Opps Created'!$E:$E,'Opps Created'!$O:$O,"Alliances",'Opps Created'!$G:$G,">="&EOMONTH($B21,-1)+1,'Opps Created'!$G:$G,"<="&EOMONTH($B21,0)), SUMIFS('Opps Created'!$E:$E,'Opps Created'!$O:$O,"Cold",'Opps Created'!$G:$G,">="&EOMONTH($B21,-1)+1,'Opps Created'!$G:$G,"<="&EOMONTH($B21,0)) ) -> 4904592 | E21: =SUMIFS('Digital Leads Raw'!$B:$B,'Digital Leads Raw'!$E:$E,">="&EOMONTH($B21,-1)+1,'Digital Leads Raw'!$E:$E,"<="&EOMONTH($B21,0)) +SUMIFS('Event Spend Raw'!$D:$D,'Event Spend Raw'!$G:$G,">="&EOMONTH($B21,-1)+1,'Event Spend Raw'!$G:$G,"<="&EOMONTH($B21,0)) +COUNTIFS('Cold outreach data'!$K:$K,"Cold",'Cold outreach data'!$C:$C,">="&EOMONTH($B21,-1)+1,'Cold outreach data'!$C:$C,"<="&EOMONTH($B21,0)) +COUNTIFS('Alliances Data Raw'!$Q:$Q,">="&EOMONTH($B21,-1)+1,'Alliances Data Raw'!$Q:$Q,"<="&EOMONTH($B21,0),'Alliances Data Raw'!$D:$D,"<>Disqualified",'Alliances Data Raw'!$D:$D,"<>Register Lead") -> 5 | F21: =COUNTIFS('Cold outreach data'!$G:$G,"Yes",'Cold outreach data'!$K:$K,"Digital",'Cold outreach data'!$C:$C,">="&EOMONTH($B21,-1)+1,'Cold outreach data'!$C:$C,"<="&EOMONTH($B21,0))+COUNTIFS('Cold outreach data'!$G:$G,"Yes",'Cold outreach data'!$K:$K,"Event",'Cold outreach data'!$C:$C,">="&EOMONTH($B21,-1)+1,'Cold outreach data'!$C:$C,"<="&EOMONTH($B21,0))+COUNTIFS('Cold outreach data'!$G:$G,"Yes",'Cold outreach data'!$K:$K,"Cold",'Cold outreach data'!$C:$C,">="&EOMONTH($B21,-1)+1,'Cold outreach data'!$C:$C,"<="&EOMONTH($B21,0))+COUNTIFS('Alliances Data Raw'!$W:$W,">="&EOMONTH($B21,-1)+1,'Alliances Data Raw'!$W:$W,"<="&EOMONTH($B21,0)) -> 7 | G21: =D21/C21 -> 700656 | H21: =SUMIFS( Table1[Total Net New ACV], Table1[LateStage_Unique_Monthly_Flag], 1, Table1[Change Date], ">="&EOMONTH('Marketing Dashboard'!B21,-1)+1, Table1[Change Date], "<="&EOMONTH('Marketing Dashboard'!B21,0) ) -> 433860 | J21: TOTAL | K21: =SUM(K17:K20) -> 75325.15 | L21: =SUM(L17:L20) -> 83937.21 | M21: =IF(L21=0,"", IF((K21-L21)/L21>0, "↑ "&TEXT((K21-L21)/L21,"0.0%"), IF((K21-L21)/L21<0, "↓ "&TEXT(ABS((K21-L21)/L21),"0.0%"), "→ 0.0%" ))) -> ↓ 10.3% | O21: TOTAL | P21: =SUM(P17:P20) -> 118 | Q21: =IFERROR((Q17*P17+Q18*P18+Q19*P19+Q20*P20)/P21,0) -> 375649.51 | R21: =IFERROR((R17*P17+R18*P18+R19*P19+R20*P20)/P21,0) -> 0.87288136 | S21: =IFERROR((S17*P17+S18*P18+S19*P19+S20*P20)/P21,0) -> 298.74576 | T21: =IFERROR((T17*P17+T18*P18+T19*P19+T20*P20)/P21,0) -> 176.05932 | U21: =IFERROR((U17*P17+U18*P18+U19*P19+U20*P20)/P21,0) -> 0.076271186
B22: =EOMONTH($AB$3,-6) -> 46053 | C22: =COUNTIFS('Opps Created'!$G:$G,">="&EOMONTH($B22,-1)+1,'Opps Created'!$G:$G,"<="&EOMONTH($B22,0),'Opps Created'!$O:$O,"<>",'Opps Created'!$O:$O,"<>0",'Opps Created'!$O:$O,"<>Exclude") -> 6 | D22: =SUM( SUMIFS('Opps Created'!$E:$E,'Opps Created'!$O:$O,"Digital",'Opps Created'!$G:$G,">="&EOMONTH($B22,-1)+1,'Opps Created'!$G:$G,"<="&EOMONTH($B22,0)), SUMIFS('Opps Created'!$E:$E,'Opps Created'!$O:$O,"Events",'Opps Created'!$G:$G,">="&EOMONTH($B22,-1)+1,'Opps Created'!$G:$G,"<="&EOMONTH($B22,0)), SUMIFS('Opps Created'!$E:$E,'Opps Created'!$O:$O,"Alliances",'Opps Created'!$G:$G,">="&EOMONTH($B22,-1)+1,'Opps Created'!$G:$G,"<="&EOMONTH($B22,0)), SUMIFS('Opps Created'!$E:$E,'Opps Created'!$O:$O,"Cold",'Opps Created'!$G:$G,">="&EOMONTH($B22,-1)+1,'Opps Created'!$G:$G,"<="&EOMONTH($B22,0)) ) -> 1915920 | E22: =SUMIFS('Digital Leads Raw'!$B:$B,'Digital Leads Raw'!$E:$E,">="&EOMONTH($B22,-1)+1,'Digital Leads Raw'!$E:$E,"<="&EOMONTH($B22,0)) +SUMIFS('Event Spend Raw'!$D:$D,'Event Spend Raw'!$G:$G,">="&EOMONTH($B22,-1)+1,'Event Spend Raw'!$G:$G,"<="&EOMONTH($B22,0)) +COUNTIFS('Cold outreach data'!$K:$K,"Cold",'Cold outreach data'!$C:$C,">="&EOMONTH($B22,-1)+1,'Cold outreach data'!$C:$C,"<="&EOMONTH($B22,0)) +COUNTIFS('Alliances Data Raw'!$Q:$Q,">="&EOMONTH($B22,-1)+1,'Alliances Data Raw'!$Q:$Q,"<="&EOMONTH($B22,0),'Alliances Data Raw'!$D:$D,"<>Disqualified",'Alliances Data Raw'!$D:$D,"<>Register Lead") -> 109 | F22: =COUNTIFS('Cold outreach data'!$G:$G,"Yes",'Cold outreach data'!$K:$K,"Digital",'Cold outreach data'!$C:$C,">="&EOMONTH($B22,-1)+1,'Cold outreach data'!$C:$C,"<="&EOMONTH($B22,0))+COUNTIFS('Cold outreach data'!$G:$G,"Yes",'Cold outreach data'!$K:$K,"Event",'Cold outreach data'!$C:$C,">="&EOMONTH($B22,-1)+1,'Cold outreach data'!$C:$C,"<="&EOMONTH($B22,0))+COUNTIFS('Cold outreach data'!$G:$G,"Yes",'Cold outreach data'!$K:$K,"Cold",'Cold outreach data'!$C:$C,">="&EOMONTH($B22,-1)+1,'Cold outreach data'!$C:$C,"<="&EOMONTH($B22,0))+COUNTIFS('Alliances Data Raw'!$W:$W,">="&EOMONTH($B22,-1)+1,'Alliances Data Raw'!$W:$W,"<="&EOMONTH($B22,0)) -> 28 | G22: =D22/C22 -> 319320 | H22: =SUMIFS( Table1[Total Net New ACV], Table1[LateStage_Unique_Monthly_Flag], 1, Table1[Change Date], ">="&EOMONTH('Marketing Dashboard'!B22,-1)+1, Table1[Change Date], "<="&EOMONTH('Marketing Dashboard'!B22,0) ) -> 317625
B23: =EOMONTH($AB$3,-5) -> 46081 | C23: =COUNTIFS('Opps Created'!$G:$G,">="&EOMONTH($B23,-1)+1,'Opps Created'!$G:$G,"<="&EOMONTH($B23,0),'Opps Created'!$O:$O,"<>",'Opps Created'!$O:$O,"<>0",'Opps Created'!$O:$O,"<>Exclude") -> 6 | D23: =SUM( SUMIFS('Opps Created'!$E:$E,'Opps Created'!$O:$O,"Digital",'Opps Created'!$G:$G,">="&EOMONTH($B23,-1)+1,'Opps Created'!$G:$G,"<="&EOMONTH($B23,0)), SUMIFS('Opps Created'!$E:$E,'Opps Created'!$O:$O,"Events",'Opps Created'!$G:$G,">="&EOMONTH($B23,-1)+1,'Opps Created'!$G:$G,"<="&EOMONTH($B23,0)), SUMIFS('Opps Created'!$E:$E,'Opps Created'!$O:$O,"Alliances",'Opps Created'!$G:$G,">="&EOMONTH($B23,-1)+1,'Opps Created'!$G:$G,"<="&EOMONTH($B23,0)), SUMIFS('Opps Created'!$E:$E,'Opps Created'!$O:$O,"Cold",'Opps Created'!$G:$G,">="&EOMONTH($B23,-1)+1,'Opps Created'!$G:$G,"<="&EOMONTH($B23,0)) ) -> 5621930 | E23: =SUMIFS('Digital Leads Raw'!$B:$B,'Digital Leads Raw'!$E:$E,">="&EOMONTH($B23,-1)+1,'Digital Leads Raw'!$E:$E,"<="&EOMONTH($B23,0)) +SUMIFS('Event Spend Raw'!$D:$D,'Event Spend Raw'!$G:$G,">="&EOMONTH($B23,-1)+1,'Event Spend Raw'!$G:$G,"<="&EOMONTH($B23,0)) +COUNTIFS('Cold outreach data'!$K:$K,"Cold",'Cold outreach data'!$C:$C,">="&EOMONTH($B23,-1)+1,'Cold outreach data'!$C:$C,"<="&EOMONTH($B23,0)) +COUNTIFS('Alliances Data Raw'!$Q:$Q,">="&EOMONTH($B23,-1)+1,'Alliances Data Raw'!$Q:$Q,"<="&EOMONTH($B23,0),'Alliances Data Raw'!$D:$D,"<>Disqualified",'Alliances Data Raw'!$D:$D,"<>Register Lead") -> 50 | F23: =COUNTIFS('Cold outreach data'!$G:$G,"Yes",'Cold outreach data'!$K:$K,"Digital",'Cold outreach data'!$C:$C,">="&EOMONTH($B23,-1)+1,'Cold outreach data'!$C:$C,"<="&EOMONTH($B23,0))+COUNTIFS('Cold outreach data'!$G:$G,"Yes",'Cold outreach data'!$K:$K,"Event",'Cold outreach data'!$C:$C,">="&EOMONTH($B23,-1)+1,'Cold outreach data'!$C:$C,"<="&EOMONTH($B23,0))+COUNTIFS('Cold outreach data'!$G:$G,"Yes",'Cold outreach data'!$K:$K,"Cold",'Cold outreach data'!$C:$C,">="&EOMONTH($B23,-1)+1,'Cold outreach data'!$C:$C,"<="&EOMONTH($B23,0))+COUNTIFS('Alliances Data Raw'!$W:$W,">="&EOMONTH($B23,-1)+1,'Alliances Data Raw'!$W:$W,"<="&EOMONTH($B23,0)) -> 28 | G23: =D23/C23 -> 936988.33 | H23: =SUMIFS( Table1[Total Net New ACV], Table1[LateStage_Unique_Monthly_Flag], 1, Table1[Change Date], ">="&EOMONTH('Marketing Dashboard'!B23,-1)+1, Table1[Change Date], "<="&EOMONTH('Marketing Dashboard'!B23,0) ) -> 2272163.4 | J23: Aging & Velocity by Channel | S23: Aging & Velocity — Median (Outlier-Resistant)
B24: =EOMONTH($AB$3,-4) -> 46112 | C24: =COUNTIFS('Opps Created'!$G:$G,">="&EOMONTH($B24,-1)+1,'Opps Created'!$G:$G,"<="&EOMONTH($B24,0),'Opps Created'!$O:$O,"<>",'Opps Created'!$O:$O,"<>0",'Opps Created'!$O:$O,"<>Exclude") -> 6 | D24: =SUM( SUMIFS('Opps Created'!$E:$E,'Opps Created'!$O:$O,"Digital",'Opps Created'!$G:$G,">="&EOMONTH($B24,-1)+1,'Opps Created'!$G:$G,"<="&EOMONTH($B24,0)), SUMIFS('Opps Created'!$E:$E,'Opps Created'!$O:$O,"Events",'Opps Created'!$G:$G,">="&EOMONTH($B24,-1)+1,'Opps Created'!$G:$G,"<="&EOMONTH($B24,0)), SUMIFS('Opps Created'!$E:$E,'Opps Created'!$O:$O,"Alliances",'Opps Created'!$G:$G,">="&EOMONTH($B24,-1)+1,'Opps Created'!$G:$G,"<="&EOMONTH($B24,0)), SUMIFS('Opps Created'!$E:$E,'Opps Created'!$O:$O,"Cold",'Opps Created'!$G:$G,">="&EOMONTH($B24,-1)+1,'Opps Created'!$G:$G,"<="&EOMONTH($B24,0)) ) -> 1187160 | E24: =SUMIFS('Digital Leads Raw'!$B:$B,'Digital Leads Raw'!$E:$E,">="&EOMONTH($B24,-1)+1,'Digital Leads Raw'!$E:$E,"<="&EOMONTH($B24,0)) +SUMIFS('Event Spend Raw'!$D:$D,'Event Spend Raw'!$G:$G,">="&EOMONTH($B24,-1)+1,'Event Spend Raw'!$G:$G,"<="&EOMONTH($B24,0)) +COUNTIFS('Cold outreach data'!$K:$K,"Cold",'Cold outreach data'!$C:$C,">="&EOMONTH($B24,-1)+1,'Cold outreach data'!$C:$C,"<="&EOMONTH($B24,0)) +COUNTIFS('Alliances Data Raw'!$Q:$Q,">="&EOMONTH($B24,-1)+1,'Alliances Data Raw'!$Q:$Q,"<="&EOMONTH($B24,0),'Alliances Data Raw'!$D:$D,"<>Disqualified",'Alliances Data Raw'!$D:$D,"<>Register Lead") -> 65 | F24: =COUNTIFS('Cold outreach data'!$G:$G,"Yes",'Cold outreach data'!$K:$K,"Digital",'Cold outreach data'!$C:$C,">="&EOMONTH($B24,-1)+1,'Cold outreach data'!$C:$C,"<="&EOMONTH($B24,0))+COUNTIFS('Cold outreach data'!$G:$G,"Yes",'Cold outreach data'!$K:$K,"Event",'Cold outreach data'!$C:$C,">="&EOMONTH($B24,-1)+1,'Cold outreach data'!$C:$C,"<="&EOMONTH($B24,0))+COUNTIFS('Cold outreach data'!$G:$G,"Yes",'Cold outreach data'!$K:$K,"Cold",'Cold outreach data'!$C:$C,">="&EOMONTH($B24,-1)+1,'Cold outreach data'!$C:$C,"<="&EOMONTH($B24,0))+COUNTIFS('Alliances Data Raw'!$W:$W,">="&EOMONTH($B24,-1)+1,'Alliances Data Raw'!$W:$W,"<="&EOMONTH($B24,0)) -> 26 | G24: =D24/C24 -> 197860 | H24: =SUMIFS( Table1[Total Net New ACV], Table1[LateStage_Unique_Monthly_Flag], 1, Table1[Change Date], ">="&EOMONTH('Marketing Dashboard'!B24,-1)+1, Table1[Change Date], "<="&EOMONTH('Marketing Dashboard'!B24,0) ) -> 2085754.8 | J24: Channel | K24: Days to Late Stage | L24: Late Stage to Won | M24: Days to Won | N24: Avg Open Opp Age | O24: Avg Open Late | P24: Late Stage Deals 30+ Days | Q24: Avg Stage Duration | S24: Channel | T24: Median Days to Late Stage | U24: Median Late Stage to Won | V24: Median Days to Won | W24: Median Open Opp Age | X24: Median Open Late
B25: =EOMONTH($AB$3,-3) -> 46142 | C25: =COUNTIFS('Opps Created'!$G:$G,">="&EOMONTH($B25,-1)+1,'Opps Created'!$G:$G,"<="&EOMONTH($B25,0),'Opps Created'!$O:$O,"<>",'Opps Created'!$O:$O,"<>0",'Opps Created'!$O:$O,"<>Exclude") -> 5 | D25: =SUM( SUMIFS('Opps Created'!$E:$E,'Opps Created'!$O:$O,"Digital",'Opps Created'!$G:$G,">="&EOMONTH($B25,-1)+1,'Opps Created'!$G:$G,"<="&EOMONTH($B25,0)), SUMIFS('Opps Created'!$E:$E,'Opps Created'!$O:$O,"Events",'Opps Created'!$G:$G,">="&EOMONTH($B25,-1)+1,'Opps Created'!$G:$G,"<="&EOMONTH($B25,0)), SUMIFS('Opps Created'!$E:$E,'Opps Created'!$O:$O,"Alliances",'Opps Created'!$G:$G,">="&EOMONTH($B25,-1)+1,'Opps Created'!$G:$G,"<="&EOMONTH($B25,0)), SUMIFS('Opps Created'!$E:$E,'Opps Created'!$O:$O,"Cold",'Opps Created'!$G:$G,">="&EOMONTH($B25,-1)+1,'Opps Created'!$G:$G,"<="&EOMONTH($B25,0)) ) -> 1314016 | E25: =SUMIFS('Digital Leads Raw'!$B:$B,'Digital Leads Raw'!$E:$E,">="&EOMONTH($B25,-1)+1,'Digital Leads Raw'!$E:$E,"<="&EOMONTH($B25,0)) +SUMIFS('Event Spend Raw'!$D:$D,'Event Spend Raw'!$G:$G,">="&EOMONTH($B25,-1)+1,'Event Spend Raw'!$G:$G,"<="&EOMONTH($B25,0)) +COUNTIFS('Cold outreach data'!$K:$K,"Cold",'Cold outreach data'!$C:$C,">="&EOMONTH($B25,-1)+1,'Cold outreach data'!$C:$C,"<="&EOMONTH($B25,0)) +COUNTIFS('Alliances Data Raw'!$Q:$Q,">="&EOMONTH($B25,-1)+1,'Alliances Data Raw'!$Q:$Q,"<="&EOMONTH($B25,0),'Alliances Data Raw'!$D:$D,"<>Disqualified",'Alliances Data Raw'!$D:$D,"<>Register Lead") -> 130 | F25: =COUNTIFS('Cold outreach data'!$G:$G,"Yes",'Cold outreach data'!$K:$K,"Digital",'Cold outreach data'!$C:$C,">="&EOMONTH($B25,-1)+1,'Cold outreach data'!$C:$C,"<="&EOMONTH($B25,0))+COUNTIFS('Cold outreach data'!$G:$G,"Yes",'Cold outreach data'!$K:$K,"Event",'Cold outreach data'!$C:$C,">="&EOMONTH($B25,-1)+1,'Cold outreach data'!$C:$C,"<="&EOMONTH($B25,0))+COUNTIFS('Cold outreach data'!$G:$G,"Yes",'Cold outreach data'!$K:$K,"Cold",'Cold outreach data'!$C:$C,">="&EOMONTH($B25,-1)+1,'Cold outreach data'!$C:$C,"<="&EOMONTH($B25,0))+COUNTIFS('Alliances Data Raw'!$W:$W,">="&EOMONTH($B25,-1)+1,'Alliances Data Raw'!$W:$W,"<="&EOMONTH($B25,0)) -> 28 | G25: =D25/C25 -> 262803.2 | H25: =SUMIFS( Table1[Total Net New ACV], Table1[LateStage_Unique_Monthly_Flag], 1, Table1[Change Date], ">="&EOMONTH('Marketing Dashboard'!B25,-1)+1, Table1[Change Date], "<="&EOMONTH('Marketing Dashboard'!B25,0) ) -> 720770 | J25: Digital | K25: =IFERROR(ROUND(AVERAGEIFS(Table1[Days Created to Late Stage],Table1[Channel],$J25,Table1[Current Stage Flag],1,Table1[Include in Aging Calc],TRUE,Table1[Days Created to Late Stage],">0"),0),"") -> 137 | L25: =IFERROR(ROUND(AVERAGEIFS(Table1[Days from Late Stage to Closed Won],Table1[Channel],$J25,Table1[Current Stage Flag],1,Table1[Include in Aging Calc],TRUE,Table1[Days from Late Stage to Closed Won],">0"),0),"") -> 122 | M25: =IFERROR(ROUND(AVERAGEIFS(Table1[Days Created to Won],Table1[Channel],$J25,Table1[Current Stage Flag],1,Table1[Include in Aging Calc],TRUE,Table1[Days Created to Won],">0"),0),"") -> 224 | N25: =IFERROR(ROUND(AVERAGEIFS(Table2[Opp Age (Total Age)],Table2[Channel],$J25,Table2[Closed Flag],0,Table2[Include in Aging Calc],TRUE,Table2[Opp Age (Total Age)],">0"),0),"") -> 534 | O25: =IFERROR(ROUND(AVERAGEIFS(Table2[Opp Age (Total Age)],Table2[Channel],$J25,Table2[Late Stage Flag],1,Table2[Closed Flag],0,Table2[Include in Aging Calc],TRUE,Table2[Opp Age (Total Age)],">0"),0),"") | P25: =COUNTIFS( 'Opps Created'!$O:$O,$J25, 'Opps Created'!$Q:$Q,1, 'Opps Created'!$R:$R,0, 'Opps Created'!$P:$P,">30" ) -> 1 | Q25: =IFERROR( ROUND( AVERAGEIFS( 'Opps Created'!$N:$N, 'Opps Created'!$O:$O,$J25, 'Opps Created'!$R:$R,0, 'Opps Created'!$N:$N,">0" ),0), "" ) -> 278 | S25: =$J25 -> Digital | T25: ='Aging Detail'!B6 -> 155 | U25: ='Aging Detail'!C6 -> 126 | V25: ='Aging Detail'!D6 -> 173 | W25: ='Aging Detail'!E6 -> 542 | X25: ='Aging Detail'!F6
B26: =EOMONTH($AB$3,-2) -> 46173 | C26: =COUNTIFS('Opps Created'!$G:$G,">="&EOMONTH($B26,-1)+1,'Opps Created'!$G:$G,"<="&EOMONTH($B26,0),'Opps Created'!$O:$O,"<>",'Opps Created'!$O:$O,"<>0",'Opps Created'!$O:$O,"<>Exclude") -> 7 | D26: =SUM( SUMIFS('Opps Created'!$E:$E,'Opps Created'!$O:$O,"Digital",'Opps Created'!$G:$G,">="&EOMONTH($B26,-1)+1,'Opps Created'!$G:$G,"<="&EOMONTH($B26,0)), SUMIFS('Opps Created'!$E:$E,'Opps Created'!$O:$O,"Events",'Opps Created'!$G:$G,">="&EOMONTH($B26,-1)+1,'Opps Created'!$G:$G,"<="&EOMONTH($B26,0)), SUMIFS('Opps Created'!$E:$E,'Opps Created'!$O:$O,"Alliances",'Opps Created'!$G:$G,">="&EOMONTH($B26,-1)+1,'Opps Created'!$G:$G,"<="&EOMONTH($B26,0)), SUMIFS('Opps Created'!$E:$E,'Opps Created'!$O:$O,"Cold",'Opps Created'!$G:$G,">="&EOMONTH($B26,-1)+1,'Opps Created'!$G:$G,"<="&EOMONTH($B26,0)) ) -> 2319060 | E26: =SUMIFS('Digital Leads Raw'!$B:$B,'Digital Leads Raw'!$E:$E,">="&EOMONTH($B26,-1)+1,'Digital Leads Raw'!$E:$E,"<="&EOMONTH($B26,0)) +SUMIFS('Event Spend Raw'!$D:$D,'Event Spend Raw'!$G:$G,">="&EOMONTH($B26,-1)+1,'Event Spend Raw'!$G:$G,"<="&EOMONTH($B26,0)) +COUNTIFS('Cold outreach data'!$K:$K,"Cold",'Cold outreach data'!$C:$C,">="&EOMONTH($B26,-1)+1,'Cold outreach data'!$C:$C,"<="&EOMONTH($B26,0)) +COUNTIFS('Alliances Data Raw'!$Q:$Q,">="&EOMONTH($B26,-1)+1,'Alliances Data Raw'!$Q:$Q,"<="&EOMONTH($B26,0),'Alliances Data Raw'!$D:$D,"<>Disqualified",'Alliances Data Raw'!$D:$D,"<>Register Lead") -> 36 | F26: =COUNTIFS('Cold outreach data'!$G:$G,"Yes",'Cold outreach data'!$K:$K,"Digital",'Cold outreach data'!$C:$C,">="&EOMONTH($B26,-1)+1,'Cold outreach data'!$C:$C,"<="&EOMONTH($B26,0))+COUNTIFS('Cold outreach data'!$G:$G,"Yes",'Cold outreach data'!$K:$K,"Event",'Cold outreach data'!$C:$C,">="&EOMONTH($B26,-1)+1,'Cold outreach data'!$C:$C,"<="&EOMONTH($B26,0))+COUNTIFS('Cold outreach data'!$G:$G,"Yes",'Cold outreach data'!$K:$K,"Cold",'Cold outreach data'!$C:$C,">="&EOMONTH($B26,-1)+1,'Cold outreach data'!$C:$C,"<="&EOMONTH($B26,0))+COUNTIFS('Alliances Data Raw'!$W:$W,">="&EOMONTH($B26,-1)+1,'Alliances Data Raw'!$W:$W,"<="&EOMONTH($B26,0)) -> 26 | G26: =D26/C26 -> 331294.29 | H26: =SUMIFS( Table1[Total Net New ACV], Table1[LateStage_Unique_Monthly_Flag], 1, Table1[Change Date], ">="&EOMONTH('Marketing Dashboard'!B26,-1)+1, Table1[Change Date], "<="&EOMONTH('Marketing Dashboard'!B26,0) ) -> 121585.47 | J26: Events | K26: =IFERROR(ROUND(AVERAGEIFS(Table1[Days Created to Late Stage],Table1[Channel],$J26,Table1[Current Stage Flag],1,Table1[Include in Aging Calc],TRUE,Table1[Days Created to Late Stage],">0"),0),"") -> 231 | L26: =IFERROR(ROUND(AVERAGEIFS(Table1[Days from Late Stage to Closed Won],Table1[Channel],$J26,Table1[Current Stage Flag],1,Table1[Include in Aging Calc],TRUE,Table1[Days from Late Stage to Closed Won],">0"),0),"") | M26: =IFERROR(ROUND(AVERAGEIFS(Table1[Days Created to Won],Table1[Channel],$J26,Table1[Current Stage Flag],1,Table1[Include in Aging Calc],TRUE,Table1[Days Created to Won],">0"),0),"") | N26: =IFERROR(ROUND(AVERAGEIFS(Table2[Opp Age (Total Age)],Table2[Channel],$J26,Table2[Closed Flag],0,Table2[Include in Aging Calc],TRUE,Table2[Opp Age (Total Age)],">0"),0),"") -> 514 | O26: =IFERROR(ROUND(AVERAGEIFS(Table2[Opp Age (Total Age)],Table2[Channel],$J26,Table2[Late Stage Flag],1,Table2[Closed Flag],0,Table2[Include in Aging Calc],TRUE,Table2[Opp Age (Total Age)],">0"),0),"") -> 318 | P26: =COUNTIFS( 'Opps Created'!$O:$O,$J26, 'Opps Created'!$Q:$Q,1, 'Opps Created'!$R:$R,0, 'Opps Created'!$P:$P,">30" ) -> 4 | Q26: =IFERROR( ROUND( AVERAGEIFS( 'Opps Created'!$N:$N, 'Opps Created'!$O:$O,$J26, 'Opps Created'!$R:$R,0, 'Opps Created'!$N:$N,">0" ),0), "" ) -> 286 | S26: =$J26 -> Events | T26: ='Aging Detail'!B7 -> 138 | U26: ='Aging Detail'!C7 | V26: ='Aging Detail'!D7 | W26: ='Aging Detail'!E7 -> 429 | X26: ='Aging Detail'!F7 -> 215
B27: =EOMONTH($AB$3,-1) -> 46203 | C27: =COUNTIFS('Opps Created'!$G:$G,">="&EOMONTH($B27,-1)+1,'Opps Created'!$G:$G,"<="&EOMONTH($B27,0),'Opps Created'!$O:$O,"<>",'Opps Created'!$O:$O,"<>0",'Opps Created'!$O:$O,"<>Exclude") -> 5 | D27: =SUM( SUMIFS('Opps Created'!$E:$E,'Opps Created'!$O:$O,"Digital",'Opps Created'!$G:$G,">="&EOMONTH($B27,-1)+1,'Opps Created'!$G:$G,"<="&EOMONTH($B27,0)), SUMIFS('Opps Created'!$E:$E,'Opps Created'!$O:$O,"Events",'Opps Created'!$G:$G,">="&EOMONTH($B27,-1)+1,'Opps Created'!$G:$G,"<="&EOMONTH($B27,0)), SUMIFS('Opps Created'!$E:$E,'Opps Created'!$O:$O,"Alliances",'Opps Created'!$G:$G,">="&EOMONTH($B27,-1)+1,'Opps Created'!$G:$G,"<="&EOMONTH($B27,0)), SUMIFS('Opps Created'!$E:$E,'Opps Created'!$O:$O,"Cold",'Opps Created'!$G:$G,">="&EOMONTH($B27,-1)+1,'Opps Created'!$G:$G,"<="&EOMONTH($B27,0)) ) -> 727080 | E27: =SUMIFS('Digital Leads Raw'!$B:$B,'Digital Leads Raw'!$E:$E,">="&EOMONTH($B27,-1)+1,'Digital Leads Raw'!$E:$E,"<="&EOMONTH($B27,0)) +SUMIFS('Event Spend Raw'!$D:$D,'Event Spend Raw'!$G:$G,">="&EOMONTH($B27,-1)+1,'Event Spend Raw'!$G:$G,"<="&EOMONTH($B27,0)) +COUNTIFS('Cold outreach data'!$K:$K,"Cold",'Cold outreach data'!$C:$C,">="&EOMONTH($B27,-1)+1,'Cold outreach data'!$C:$C,"<="&EOMONTH($B27,0)) +COUNTIFS('Alliances Data Raw'!$Q:$Q,">="&EOMONTH($B27,-1)+1,'Alliances Data Raw'!$Q:$Q,"<="&EOMONTH($B27,0),'Alliances Data Raw'!$D:$D,"<>Disqualified",'Alliances Data Raw'!$D:$D,"<>Register Lead") -> 16 | F27: =COUNTIFS('Cold outreach data'!$G:$G,"Yes",'Cold outreach data'!$K:$K,"Digital",'Cold outreach data'!$C:$C,">="&EOMONTH($B27,-1)+1,'Cold outreach data'!$C:$C,"<="&EOMONTH($B27,0))+COUNTIFS('Cold outreach data'!$G:$G,"Yes",'Cold outreach data'!$K:$K,"Event",'Cold outreach data'!$C:$C,">="&EOMONTH($B27,-1)+1,'Cold outreach data'!$C:$C,"<="&EOMONTH($B27,0))+COUNTIFS('Cold outreach data'!$G:$G,"Yes",'Cold outreach data'!$K:$K,"Cold",'Cold outreach data'!$C:$C,">="&EOMONTH($B27,-1)+1,'Cold outreach data'!$C:$C,"<="&EOMONTH($B27,0))+COUNTIFS('Alliances Data Raw'!$W:$W,">="&EOMONTH($B27,-1)+1,'Alliances Data Raw'!$W:$W,"<="&EOMONTH($B27,0)) -> 10 | G27: =D27/C27 -> 145416 | H27: =SUMIFS( Table1[Total Net New ACV], Table1[LateStage_Unique_Monthly_Flag], 1, Table1[Change Date], ">="&EOMONTH('Marketing Dashboard'!B27,-1)+1, Table1[Change Date], "<="&EOMONTH('Marketing Dashboard'!B27,0) ) -> 1270750 | J27: Cold | K27: =IFERROR(ROUND(AVERAGEIFS(Table1[Days Created to Late Stage],Table1[Channel],$J27,Table1[Current Stage Flag],1,Table1[Include in Aging Calc],TRUE,Table1[Days Created to Late Stage],">0"),0),"") -> 240 | L27: =IFERROR(ROUND(AVERAGEIFS(Table1[Days from Late Stage to Closed Won],Table1[Channel],$J27,Table1[Current Stage Flag],1,Table1[Include in Aging Calc],TRUE,Table1[Days from Late Stage to Closed Won],">0"),0),"") -> 28 | M27: =IFERROR(ROUND(AVERAGEIFS(Table1[Days Created to Won],Table1[Channel],$J27,Table1[Current Stage Flag],1,Table1[Include in Aging Calc],TRUE,Table1[Days Created to Won],">0"),0),"") -> 171 | N27: =IFERROR(ROUND(AVERAGEIFS(Table2[Opp Age (Total Age)],Table2[Channel],$J27,Table2[Closed Flag],0,Table2[Include in Aging Calc],TRUE,Table2[Opp Age (Total Age)],">0"),0),"") -> 792 | O27: =IFERROR(ROUND(AVERAGEIFS(Table2[Opp Age (Total Age)],Table2[Channel],$J27,Table2[Late Stage Flag],1,Table2[Closed Flag],0,Table2[Include in Aging Calc],TRUE,Table2[Opp Age (Total Age)],">0"),0),"") -> 360 | P27: =COUNTIFS( 'Opps Created'!$O:$O,$J27, 'Opps Created'!$Q:$Q,1, 'Opps Created'!$R:$R,0, 'Opps Created'!$P:$P,">30" ) -> 2 | Q27: =IFERROR( ROUND( AVERAGEIFS( 'Opps Created'!$N:$N, 'Opps Created'!$O:$O,$J27, 'Opps Created'!$R:$R,0, 'Opps Created'!$N:$N,">0" ),0), "" ) -> 434 | S27: =$J27 -> Cold | T27: ='Aging Detail'!B8 -> 191 | U27: ='Aging Detail'!C8 -> 19 | V27: ='Aging Detail'!D8 -> 82 | W27: ='Aging Detail'!E8 -> 790 | X27: ='Aging Detail'!F8 -> 360
B28: =$AB$3 -> 46234 | C28: =COUNTIFS('Opps Created'!$G:$G,">="&EOMONTH($B28,-1)+1,'Opps Created'!$G:$G,"<="&EOMONTH($B28,0),'Opps Created'!$O:$O,"<>",'Opps Created'!$O:$O,"<>0",'Opps Created'!$O:$O,"<>Exclude") -> 10 | D28: =SUM( SUMIFS('Opps Created'!$E:$E,'Opps Created'!$O:$O,"Digital",'Opps Created'!$G:$G,">="&EOMONTH($B28,-1)+1,'Opps Created'!$G:$G,"<="&EOMONTH($B28,0)), SUMIFS('Opps Created'!$E:$E,'Opps Created'!$O:$O,"Events",'Opps Created'!$G:$G,">="&EOMONTH($B28,-1)+1,'Opps Created'!$G:$G,"<="&EOMONTH($B28,0)), SUMIFS('Opps Created'!$E:$E,'Opps Created'!$O:$O,"Alliances",'Opps Created'!$G:$G,">="&EOMONTH($B28,-1)+1,'Opps Created'!$G:$G,"<="&EOMONTH($B28,0)), SUMIFS('Opps Created'!$E:$E,'Opps Created'!$O:$O,"Cold",'Opps Created'!$G:$G,">="&EOMONTH($B28,-1)+1,'Opps Created'!$G:$G,"<="&EOMONTH($B28,0)) ) -> 6517080 | E28: =SUMIFS('Digital Leads Raw'!$B:$B,'Digital Leads Raw'!$E:$E,">="&EOMONTH($B28,-1)+1,'Digital Leads Raw'!$E:$E,"<="&EOMONTH($B28,0)) +SUMIFS('Event Spend Raw'!$D:$D,'Event Spend Raw'!$G:$G,">="&EOMONTH($B28,-1)+1,'Event Spend Raw'!$G:$G,"<="&EOMONTH($B28,0)) +COUNTIFS('Cold outreach data'!$K:$K,"Cold",'Cold outreach data'!$C:$C,">="&EOMONTH($B28,-1)+1,'Cold outreach data'!$C:$C,"<="&EOMONTH($B28,0)) +COUNTIFS('Alliances Data Raw'!$Q:$Q,">="&EOMONTH($B28,-1)+1,'Alliances Data Raw'!$Q:$Q,"<="&EOMONTH($B28,0),'Alliances Data Raw'!$D:$D,"<>Disqualified",'Alliances Data Raw'!$D:$D,"<>Register Lead") -> 17 | F28: =COUNTIFS('Cold outreach data'!$G:$G,"Yes",'Cold outreach data'!$K:$K,"Digital",'Cold outreach data'!$C:$C,">="&EOMONTH($B28,-1)+1,'Cold outreach data'!$C:$C,"<="&EOMONTH($B28,0))+COUNTIFS('Cold outreach data'!$G:$G,"Yes",'Cold outreach data'!$K:$K,"Event",'Cold outreach data'!$C:$C,">="&EOMONTH($B28,-1)+1,'Cold outreach data'!$C:$C,"<="&EOMONTH($B28,0))+COUNTIFS('Cold outreach data'!$G:$G,"Yes",'Cold outreach data'!$K:$K,"Cold",'Cold outreach data'!$C:$C,">="&EOMONTH($B28,-1)+1,'Cold outreach data'!$C:$C,"<="&EOMONTH($B28,0))+COUNTIFS('Alliances Data Raw'!$W:$W,">="&EOMONTH($B28,-1)+1,'Alliances Data Raw'!$W:$W,"<="&EOMONTH($B28,0)) -> 13 | G28: =D28/C28 -> 651708 | H28: =SUMIFS( Table1[Total Net New ACV], Table1[LateStage_Unique_Monthly_Flag], 1, Table1[Change Date], ">="&EOMONTH('Marketing Dashboard'!B28,-1)+1, Table1[Change Date], "<="&EOMONTH('Marketing Dashboard'!B28,0) ) -> 2291910.6 | J28: Alliances | K28: =IFERROR(ROUND(AVERAGEIFS(Table1[Days Created to Late Stage],Table1[Channel],$J28,Table1[Current Stage Flag],1,Table1[Include in Aging Calc],TRUE,Table1[Days Created to Late Stage],">0"),0),"") -> 153 | L28: =IFERROR(ROUND(AVERAGEIFS(Table1[Days from Late Stage to Closed Won],Table1[Channel],$J28,Table1[Current Stage Flag],1,Table1[Include in Aging Calc],TRUE,Table1[Days from Late Stage to Closed Won],">0"),0),"") -> 61 | M28: =IFERROR(ROUND(AVERAGEIFS(Table1[Days Created to Won],Table1[Channel],$J28,Table1[Current Stage Flag],1,Table1[Include in Aging Calc],TRUE,Table1[Days Created to Won],">0"),0),"") -> 225 | N28: =IFERROR(ROUND(AVERAGEIFS(Table2[Opp Age (Total Age)],Table2[Channel],$J28,Table2[Closed Flag],0,Table2[Include in Aging Calc],TRUE,Table2[Opp Age (Total Age)],">0"),0),"") -> 663 | O28: =IFERROR(ROUND(AVERAGEIFS(Table2[Opp Age (Total Age)],Table2[Channel],$J28,Table2[Late Stage Flag],1,Table2[Closed Flag],0,Table2[Include in Aging Calc],TRUE,Table2[Opp Age (Total Age)],">0"),0),"") -> 217 | P28: =COUNTIFS( 'Opps Created'!$O:$O,$J28, 'Opps Created'!$Q:$Q,1, 'Opps Created'!$R:$R,0, 'Opps Created'!$P:$P,">30" ) -> 5 | Q28: =IFERROR( ROUND( AVERAGEIFS( 'Opps Created'!$N:$N, 'Opps Created'!$O:$O,$J28, 'Opps Created'!$R:$R,0, 'Opps Created'!$N:$N,">0" ),0), "" ) -> 320 | S28: =$J28 -> Alliances | T28: ='Aging Detail'!B9 -> 94 | U28: ='Aging Detail'!C9 -> 55 | V28: ='Aging Detail'!D9 -> 170 | W28: ='Aging Detail'!E9 -> 560 | X28: ='Aging Detail'!F9 -> 201
J29: TOTAL | K29: =IFERROR(ROUND(AVERAGEIFS(Table1[Days Created to Late Stage],Table1[Current Stage Flag],1,Table1[Include in Aging Calc],TRUE,Table1[Days Created to Late Stage],">0"),0),"") -> 139 | L29: =IFERROR(ROUND(AVERAGEIFS(Table1[Days from Late Stage to Closed Won],Table1[Current Stage Flag],1,Table1[Include in Aging Calc],TRUE,Table1[Days from Late Stage to Closed Won],">0"),0),"") -> 51 | M29: =IFERROR(ROUND(AVERAGEIFS(Table1[Days Created to Won],Table1[Current Stage Flag],1,Table1[Include in Aging Calc],TRUE,Table1[Days Created to Won],">0"),0),"") -> 184 | N29: =IFERROR(ROUND(AVERAGEIFS(Table2[Opp Age (Total Age)],Table2[Closed Flag],0,Table2[Include in Aging Calc],TRUE,Table2[Opp Age (Total Age)],">0"),0),"") -> 704 | O29: =IFERROR(ROUND(AVERAGEIFS(Table2[Opp Age (Total Age)],Table2[Late Stage Flag],1,Table2[Closed Flag],0,Table2[Include in Aging Calc],TRUE,Table2[Opp Age (Total Age)],">0"),0),"") -> 490 | P29: =SUM(P25:P28) -> 12 | Q29: =IFERROR(ROUND(AVERAGEIFS('Opps Created'!$N:$N,'Opps Created'!$R:$R,0,'Opps Created'!$N:$N,">0"),0),"") -> 371 | S29: =$J29 -> TOTAL | T29: ='Aging Detail'!B10 -> 66 | U29: ='Aging Detail'!C10 -> 31 | V29: ='Aging Detail'!D10 -> 128 | W29: ='Aging Detail'!E10 -> 574 | X29: ='Aging Detail'!F10 -> 297
J31: =COUNTIF('Aging Detail'!$F$14:$F$20,FALSE)&" stale/outlier deal(s) currently excluded from the averages above — see the Aging Detail tab to review or change." -> 4 stale/outlier deal(s) currently excluded from the averages above — see the Aging Detail tab to review or change. | Q31: Open tab → | S31: ="Median view of the same filtered deals (Include in Aging Calc = TRUE) as the Average table — shows the typical deal, since Average can still be pulled up by a few large but legitimate deals. See Aging Detail tab for the deal-level filter." -> Median view of the same filtered deals (Include in Aging Calc = TRUE) as the Average table — shows the typical deal, since Average can still be pulled up by a few large but legitimate deals. See Aging Detail tab for the deal-level filter.

Sheet Aging Detail
A1: Aging & Velocity — Outlier & Median Detail
A2: Backs the Aging & Velocity by Channel section on the Marketing Dashboard tab. Flip 'Include in Aging Calc?' below to include/exclude a flagged deal from the headline averages.
A4: Median (Outlier-Resistant View)
A5: Channel | B5: Median Days to Late Stage | C5: Median Late Stage to Won | D5: Median Days to Won | E5: Median Open Opp Age | F5: Median Open Late
A6: Digital | B6: {=IFERROR(ROUND(MEDIAN(IF((Table1[Channel]=$A6)*(Table1[Current Stage Flag]=1)*(Table1[Include in Aging Calc]=TRUE)*(Table1[Days Created to Late Stage]>0),Table1[Days Created to Late Stage])),0),"")} -> 155 | C6: {=IFERROR(ROUND(MEDIAN(IF((Table1[Channel]=$A6)*(Table1[Current Stage Flag]=1)*(Table1[Include in Aging Calc]=TRUE)*(Table1[Days from Late Stage to Closed Won]>0),Table1[Days from Late Stage to Closed Won])),0),"")} -> 126 | D6: {=IFERROR(ROUND(MEDIAN(IF((Table1[Channel]=$A6)*(Table1[Current Stage Flag]=1)*(Table1[Include in Aging Calc]=TRUE)*(Table1[Days Created to Won]>0),Table1[Days Created to Won])),0),"")} -> 173 | E6: {=IFERROR(ROUND(MEDIAN(IF((Table2[Channel]=$A6)*(Table2[Closed Flag]=0)*(Table2[Include in Aging Calc]=TRUE)*(Table2[Opp Age (Total Age)]>0),Table2[Opp Age (Total Age)])),0),"")} -> 542 | F6: {=IFERROR(ROUND(MEDIAN(IF((Table2[Channel]=$A6)*(Table2[Late Stage Flag]=1)*(Table2[Closed Flag]=0)*(Table2[Include in Aging Calc]=TRUE)*(Table2[Opp Age (Total Age)]>0),Table2[Opp Age (Total Age)])),0),"")}
A7: Events | B7: {=IFERROR(ROUND(MEDIAN(IF((Table1[Channel]=$A7)*(Table1[Current Stage Flag]=1)*(Table1[Include in Aging Calc]=TRUE)*(Table1[Days Created to Late Stage]>0),Table1[Days Created to Late Stage])),0),"")} -> 138 | C7: {=IFERROR(ROUND(MEDIAN(IF((Table1[Channel]=$A7)*(Table1[Current Stage Flag]=1)*(Table1[Include in Aging Calc]=TRUE)*(Table1[Days from Late Stage to Closed Won]>0),Table1[Days from Late Stage to Closed Won])),0),"")} | D7: {=IFERROR(ROUND(MEDIAN(IF((Table1[Channel]=$A7)*(Table1[Current Stage Flag]=1)*(Table1[Include in Aging Calc]=TRUE)*(Table1[Days Created to Won]>0),Table1[Days Created to Won])),0),"")} | E7: {=IFERROR(ROUND(MEDIAN(IF((Table2[Channel]=$A7)*(Table2[Closed Flag]=0)*(Table2[Include in Aging Calc]=TRUE)*(Table2[Opp Age (Total Age)]>0),Table2[Opp Age (Total Age)])),0),"")} -> 429 | F7: {=IFERROR(ROUND(MEDIAN(IF((Table2[Channel]=$A7)*(Table2[Late Stage Flag]=1)*(Table2[Closed Flag]=0)*(Table2[Include in Aging Calc]=TRUE)*(Table2[Opp Age (Total Age)]>0),Table2[Opp Age (Total Age)])),0),"")} -> 215
A8: Cold | B8: {=IFERROR(ROUND(MEDIAN(IF((Table1[Channel]=$A8)*(Table1[Current Stage Flag]=1)*(Table1[Include in Aging Calc]=TRUE)*(Table1[Days Created to Late Stage]>0),Table1[Days Created to Late Stage])),0),"")} -> 191 | C8: {=IFERROR(ROUND(MEDIAN(IF((Table1[Channel]=$A8)*(Table1[Current Stage Flag]=1)*(Table1[Include in Aging Calc]=TRUE)*(Table1[Days from Late Stage to Closed Won]>0),Table1[Days from Late Stage to Closed Won])),0),"")} -> 19 | D8: {=IFERROR(ROUND(MEDIAN(IF((Table1[Channel]=$A8)*(Table1[Current Stage Flag]=1)*(Table1[Include in Aging Calc]=TRUE)*(Table1[Days Created to Won]>0),Table1[Days Created to Won])),0),"")} -> 82 | E8: {=IFERROR(ROUND(MEDIAN(IF((Table2[Channel]=$A8)*(Table2[Closed Flag]=0)*(Table2[Include in Aging Calc]=TRUE)*(Table2[Opp Age (Total Age)]>0),Table2[Opp Age (Total Age)])),0),"")} -> 790 | F8: {=IFERROR(ROUND(MEDIAN(IF((Table2[Channel]=$A8)*(Table2[Late Stage Flag]=1)*(Table2[Closed Flag]=0)*(Table2[Include in Aging Calc]=TRUE)*(Table2[Opp Age (Total Age)]>0),Table2[Opp Age (Total Age)])),0),"")} -> 360
A9: Alliances | B9: {=IFERROR(ROUND(MEDIAN(IF((Table1[Channel]=$A9)*(Table1[Current Stage Flag]=1)*(Table1[Include in Aging Calc]=TRUE)*(Table1[Days Created to Late Stage]>0),Table1[Days Created to Late Stage])),0),"")} -> 94 | C9: {=IFERROR(ROUND(MEDIAN(IF((Table1[Channel]=$A9)*(Table1[Current Stage Flag]=1)*(Table1[Include in Aging Calc]=TRUE)*(Table1[Days from Late Stage to Closed Won]>0),Table1[Days from Late Stage to Closed Won])),0),"")} -> 55 | D9: {=IFERROR(ROUND(MEDIAN(IF((Table1[Channel]=$A9)*(Table1[Current Stage Flag]=1)*(Table1[Include in Aging Calc]=TRUE)*(Table1[Days Created to Won]>0),Table1[Days Created to Won])),0),"")} -> 170 | E9: {=IFERROR(ROUND(MEDIAN(IF((Table2[Channel]=$A9)*(Table2[Closed Flag]=0)*(Table2[Include in Aging Calc]=TRUE)*(Table2[Opp Age (Total Age)]>0),Table2[Opp Age (Total Age)])),0),"")} -> 560 | F9: {=IFERROR(ROUND(MEDIAN(IF((Table2[Channel]=$A9)*(Table2[Late Stage Flag]=1)*(Table2[Closed Flag]=0)*(Table2[Include in Aging Calc]=TRUE)*(Table2[Opp Age (Total Age)]>0),Table2[Opp Age (Total Age)])),0),"")} -> 201
A10: TOTAL | B10: {=IFERROR(ROUND(MEDIAN(IF((Table1[Current Stage Flag]=1)*(Table1[Include in Aging Calc]=TRUE)*(Table1[Days Created to Late Stage]>0),Table1[Days Created to Late Stage])),0),"")} -> 66 | C10: {=IFERROR(ROUND(MEDIAN(IF((Table1[Current Stage Flag]=1)*(Table1[Include in Aging Calc]=TRUE)*(Table1[Days from Late Stage to Closed Won]>0),Table1[Days from Late Stage to Closed Won])),0),"")} -> 31 | D10: {=IFERROR(ROUND(MEDIAN(IF((Table1[Current Stage Flag]=1)*(Table1[Include in Aging Calc]=TRUE)*(Table1[Days Created to Won]>0),Table1[Days Created to Won])),0),"")} -> 128 | E10: {=IFERROR(ROUND(MEDIAN(IF((Table2[Closed Flag]=0)*(Table2[Include in Aging Calc]=TRUE)*(Table2[Opp Age (Total Age)]>0),Table2[Opp Age (Total Age)])),0),"")} -> 574 | F10: {=IFERROR(ROUND(MEDIAN(IF((Table2[Late Stage Flag]=1)*(Table2[Closed Flag]=0)*(Table2[Include in Aging Calc]=TRUE)*(Table2[Opp Age (Total Age)]>0),Table2[Opp Age (Total Age)])),0),"")} -> 297
A12: Outlier Watch List — Aging & Velocity
A13: Channel | B13: Opportunity / Account | C13: Metric Flagged | D13: Days | E13: Why It's Flagged | F13: Include in Aging Calc? | G13: Recommendation | H13: Opp ID (lookup key)
A14: Digital | B14: TIAA-CREF - NCC - Post Pilot / TIAA-CREF | C14: Avg Open Opp Age & Avg Open Late | D14: =ROUND(AVERAGEIFS(Table2[Opp Age (Total Age)],Table2[Opportunity ID],$H14),0) -> 1384 | E14: ="Only open, late-stage Digital deal (n="&COUNTIFS(Table2[Channel],"Digital",Table2[Late Stage Flag],1,Table2[Closed Flag],0)&") — this single deal is the entire 'Avg Open Late' figure, not a true average." -> Only open, late-stage Digital deal (n=1) — this single deal is the entire 'Avg Open Late' figure, not a true average. | F14: FALSE | G14: Exclude — n=1, not a real average | H14: 006V50000052eDA
A15: Cold | B15: Toyota Financial / Toyota Financial Services Corporation | C15: Avg Open Opp Age | D15: =ROUND(AVERAGEIFS(Table2[Opp Age (Total Age)],Table2[Opportunity ID],$H15),0) -> 2551 | E15: ="Open "&D15&" days vs. Cold Outreach median of "&$E$8&" days (~"&ROUND(D15/$E$8,1)&"x)" -> Open 2551 days vs. Cold Outreach median of 790 days (~3.2x) | F15: FALSE | G15: Exclude — stale, recommend reviewing for close-out | H15: 006V50000052Y5D
